--- Error at 2024-10-06 19:26:37.450105-07:00 ---
            Exception in main:
[36mray::unlearn()[39m (pid=909628, ip=64.255.46.66)
  File "/data2/Users/aghyad/publish_code_unlearn_eval/pipeline.py", line 183, in unlearn
    unlearn_corpus.main(
  File "/data2/Users/aghyad/publish_code_unlearn_eval/unlearn_corpus.py", line 538, in main
    retain_dataset = load_jsonl ([f"data/{file}.jsonl" for file in retain_files])
  File "/data2/Users/aghyad/publish_code_unlearn_eval/unlearn_corpus.py", line 422, in load_jsonl
    for line in open(file, "r"):
FileNotFoundError: [Errno 2] No such file or directory: 'data/fineweb_edu_seed-42/split_0.jsonl'

            Traceback:
Traceback (most recent call last):
  File "/data2/Users/aghyad/publish_code_unlearn_eval/pipeline.py", line 392, in main
    ) = ray.get(ref)
  File "/data2/Users/aghyad/venv/lib/python3.10/site-packages/ray/_private/auto_init_hook.py", line 21, in auto_init_wrapper
    return fn(*args, **kwargs)
  File "/data2/Users/aghyad/venv/lib/python3.10/site-packages/ray/_private/client_mode_hook.py", line 103, in wrapper
    return func(*args, **kwargs)
  File "/data2/Users/aghyad/venv/lib/python3.10/site-packages/ray/_private/worker.py", line 2691, in get
    values, debugger_breakpoint = worker.get_objects(object_refs, timeout=timeout)
  File "/data2/Users/aghyad/venv/lib/python3.10/site-packages/ray/_private/worker.py", line 871, in get_objects
    raise value.as_instanceof_cause()
ray.exceptions.RayTaskError(FileNotFoundError): [36mray::unlearn()[39m (pid=909628, ip=64.255.46.66)
  File "/data2/Users/aghyad/publish_code_unlearn_eval/pipeline.py", line 183, in unlearn
    unlearn_corpus.main(
  File "/data2/Users/aghyad/publish_code_unlearn_eval/unlearn_corpus.py", line 538, in main
    retain_dataset = load_jsonl ([f"data/{file}.jsonl" for file in retain_files])
  File "/data2/Users/aghyad/publish_code_unlearn_eval/unlearn_corpus.py", line 422, in load_jsonl
    for line in open(file, "r"):
FileNotFoundError: [Errno 2] No such file or directory: 'data/fineweb_edu_seed-42/split_0.jsonl'
        

--- Error at 2024-10-06 19:26:37.765874-07:00 ---
            Exception in main:
[36mray::unlearn()[39m (pid=909797, ip=64.255.46.66)
  File "/data2/Users/aghyad/publish_code_unlearn_eval/pipeline.py", line 183, in unlearn
    unlearn_corpus.main(
  File "/data2/Users/aghyad/publish_code_unlearn_eval/unlearn_corpus.py", line 538, in main
    retain_dataset = load_jsonl ([f"data/{file}.jsonl" for file in retain_files])
  File "/data2/Users/aghyad/publish_code_unlearn_eval/unlearn_corpus.py", line 422, in load_jsonl
    for line in open(file, "r"):
FileNotFoundError: [Errno 2] No such file or directory: 'data/fineweb_edu_seed-42/split_0.jsonl'

            Traceback:
Traceback (most recent call last):
  File "/data2/Users/aghyad/publish_code_unlearn_eval/pipeline.py", line 392, in main
    ) = ray.get(ref)
  File "/data2/Users/aghyad/venv/lib/python3.10/site-packages/ray/_private/auto_init_hook.py", line 21, in auto_init_wrapper
    return fn(*args, **kwargs)
  File "/data2/Users/aghyad/venv/lib/python3.10/site-packages/ray/_private/client_mode_hook.py", line 103, in wrapper
    return func(*args, **kwargs)
  File "/data2/Users/aghyad/venv/lib/python3.10/site-packages/ray/_private/worker.py", line 2691, in get
    values, debugger_breakpoint = worker.get_objects(object_refs, timeout=timeout)
  File "/data2/Users/aghyad/venv/lib/python3.10/site-packages/ray/_private/worker.py", line 871, in get_objects
    raise value.as_instanceof_cause()
ray.exceptions.RayTaskError(FileNotFoundError): [36mray::unlearn()[39m (pid=909797, ip=64.255.46.66)
  File "/data2/Users/aghyad/publish_code_unlearn_eval/pipeline.py", line 183, in unlearn
    unlearn_corpus.main(
  File "/data2/Users/aghyad/publish_code_unlearn_eval/unlearn_corpus.py", line 538, in main
    retain_dataset = load_jsonl ([f"data/{file}.jsonl" for file in retain_files])
  File "/data2/Users/aghyad/publish_code_unlearn_eval/unlearn_corpus.py", line 422, in load_jsonl
    for line in open(file, "r"):
FileNotFoundError: [Errno 2] No such file or directory: 'data/fineweb_edu_seed-42/split_0.jsonl'
        

--- Error at 2024-10-06 19:26:38.038376-07:00 ---
            Exception in main:
[36mray::unlearn()[39m (pid=909129, ip=64.255.46.66)
  File "/data2/Users/aghyad/publish_code_unlearn_eval/pipeline.py", line 183, in unlearn
    unlearn_corpus.main(
  File "/data2/Users/aghyad/publish_code_unlearn_eval/unlearn_corpus.py", line 538, in main
    retain_dataset = load_jsonl ([f"data/{file}.jsonl" for file in retain_files])
  File "/data2/Users/aghyad/publish_code_unlearn_eval/unlearn_corpus.py", line 422, in load_jsonl
    for line in open(file, "r"):
FileNotFoundError: [Errno 2] No such file or directory: 'data/fineweb_edu_seed-42/split_0.jsonl'

            Traceback:
Traceback (most recent call last):
  File "/data2/Users/aghyad/publish_code_unlearn_eval/pipeline.py", line 392, in main
    ) = ray.get(ref)
  File "/data2/Users/aghyad/venv/lib/python3.10/site-packages/ray/_private/auto_init_hook.py", line 21, in auto_init_wrapper
    return fn(*args, **kwargs)
  File "/data2/Users/aghyad/venv/lib/python3.10/site-packages/ray/_private/client_mode_hook.py", line 103, in wrapper
    return func(*args, **kwargs)
  File "/data2/Users/aghyad/venv/lib/python3.10/site-packages/ray/_private/worker.py", line 2691, in get
    values, debugger_breakpoint = worker.get_objects(object_refs, timeout=timeout)
  File "/data2/Users/aghyad/venv/lib/python3.10/site-packages/ray/_private/worker.py", line 871, in get_objects
    raise value.as_instanceof_cause()
ray.exceptions.RayTaskError(FileNotFoundError): [36mray::unlearn()[39m (pid=909129, ip=64.255.46.66)
  File "/data2/Users/aghyad/publish_code_unlearn_eval/pipeline.py", line 183, in unlearn
    unlearn_corpus.main(
  File "/data2/Users/aghyad/publish_code_unlearn_eval/unlearn_corpus.py", line 538, in main
    retain_dataset = load_jsonl ([f"data/{file}.jsonl" for file in retain_files])
  File "/data2/Users/aghyad/publish_code_unlearn_eval/unlearn_corpus.py", line 422, in load_jsonl
    for line in open(file, "r"):
FileNotFoundError: [Errno 2] No such file or directory: 'data/fineweb_edu_seed-42/split_0.jsonl'
        

--- Error at 2024-10-06 19:26:38.346121-07:00 ---
            Exception in main:
[36mray::unlearn()[39m (pid=909690, ip=64.255.46.66)
  File "/data2/Users/aghyad/publish_code_unlearn_eval/pipeline.py", line 183, in unlearn
    unlearn_corpus.main(
  File "/data2/Users/aghyad/publish_code_unlearn_eval/unlearn_corpus.py", line 538, in main
    retain_dataset = load_jsonl ([f"data/{file}.jsonl" for file in retain_files])
  File "/data2/Users/aghyad/publish_code_unlearn_eval/unlearn_corpus.py", line 422, in load_jsonl
    for line in open(file, "r"):
FileNotFoundError: [Errno 2] No such file or directory: 'data/fineweb_edu_seed-42/split_0.jsonl'

            Traceback:
Traceback (most recent call last):
  File "/data2/Users/aghyad/publish_code_unlearn_eval/pipeline.py", line 392, in main
    ) = ray.get(ref)
  File "/data2/Users/aghyad/venv/lib/python3.10/site-packages/ray/_private/auto_init_hook.py", line 21, in auto_init_wrapper
    return fn(*args, **kwargs)
  File "/data2/Users/aghyad/venv/lib/python3.10/site-packages/ray/_private/client_mode_hook.py", line 103, in wrapper
    return func(*args, **kwargs)
  File "/data2/Users/aghyad/venv/lib/python3.10/site-packages/ray/_private/worker.py", line 2691, in get
    values, debugger_breakpoint = worker.get_objects(object_refs, timeout=timeout)
  File "/data2/Users/aghyad/venv/lib/python3.10/site-packages/ray/_private/worker.py", line 871, in get_objects
    raise value.as_instanceof_cause()
ray.exceptions.RayTaskError(FileNotFoundError): [36mray::unlearn()[39m (pid=909690, ip=64.255.46.66)
  File "/data2/Users/aghyad/publish_code_unlearn_eval/pipeline.py", line 183, in unlearn
    unlearn_corpus.main(
  File "/data2/Users/aghyad/publish_code_unlearn_eval/unlearn_corpus.py", line 538, in main
    retain_dataset = load_jsonl ([f"data/{file}.jsonl" for file in retain_files])
  File "/data2/Users/aghyad/publish_code_unlearn_eval/unlearn_corpus.py", line 422, in load_jsonl
    for line in open(file, "r"):
FileNotFoundError: [Errno 2] No such file or directory: 'data/fineweb_edu_seed-42/split_0.jsonl'
        

--- Error at 2024-10-06 19:26:38.406609-07:00 ---
            Exception in main:
[36mray::unlearn()[39m (pid=909716, ip=64.255.46.66)
  File "/data2/Users/aghyad/publish_code_unlearn_eval/pipeline.py", line 183, in unlearn
    unlearn_corpus.main(
  File "/data2/Users/aghyad/publish_code_unlearn_eval/unlearn_corpus.py", line 538, in main
    retain_dataset = load_jsonl ([f"data/{file}.jsonl" for file in retain_files])
  File "/data2/Users/aghyad/publish_code_unlearn_eval/unlearn_corpus.py", line 422, in load_jsonl
    for line in open(file, "r"):
FileNotFoundError: [Errno 2] No such file or directory: 'data/fineweb_edu_seed-42/split_0.jsonl'

            Traceback:
Traceback (most recent call last):
  File "/data2/Users/aghyad/publish_code_unlearn_eval/pipeline.py", line 392, in main
    ) = ray.get(ref)
  File "/data2/Users/aghyad/venv/lib/python3.10/site-packages/ray/_private/auto_init_hook.py", line 21, in auto_init_wrapper
    return fn(*args, **kwargs)
  File "/data2/Users/aghyad/venv/lib/python3.10/site-packages/ray/_private/client_mode_hook.py", line 103, in wrapper
    return func(*args, **kwargs)
  File "/data2/Users/aghyad/venv/lib/python3.10/site-packages/ray/_private/worker.py", line 2691, in get
    values, debugger_breakpoint = worker.get_objects(object_refs, timeout=timeout)
  File "/data2/Users/aghyad/venv/lib/python3.10/site-packages/ray/_private/worker.py", line 871, in get_objects
    raise value.as_instanceof_cause()
ray.exceptions.RayTaskError(FileNotFoundError): [36mray::unlearn()[39m (pid=909716, ip=64.255.46.66)
  File "/data2/Users/aghyad/publish_code_unlearn_eval/pipeline.py", line 183, in unlearn
    unlearn_corpus.main(
  File "/data2/Users/aghyad/publish_code_unlearn_eval/unlearn_corpus.py", line 538, in main
    retain_dataset = load_jsonl ([f"data/{file}.jsonl" for file in retain_files])
  File "/data2/Users/aghyad/publish_code_unlearn_eval/unlearn_corpus.py", line 422, in load_jsonl
    for line in open(file, "r"):
FileNotFoundError: [Errno 2] No such file or directory: 'data/fineweb_edu_seed-42/split_0.jsonl'
        

--- Error at 2024-10-06 19:26:38.652559-07:00 ---
            Exception in main:
[36mray::unlearn()[39m (pid=910005, ip=64.255.46.66)
  File "/data2/Users/aghyad/publish_code_unlearn_eval/pipeline.py", line 183, in unlearn
    unlearn_corpus.main(
  File "/data2/Users/aghyad/publish_code_unlearn_eval/unlearn_corpus.py", line 538, in main
    retain_dataset = load_jsonl ([f"data/{file}.jsonl" for file in retain_files])
  File "/data2/Users/aghyad/publish_code_unlearn_eval/unlearn_corpus.py", line 422, in load_jsonl
    for line in open(file, "r"):
FileNotFoundError: [Errno 2] No such file or directory: 'data/fineweb_edu_seed-42/split_0.jsonl'

            Traceback:
Traceback (most recent call last):
  File "/data2/Users/aghyad/publish_code_unlearn_eval/pipeline.py", line 392, in main
    ) = ray.get(ref)
  File "/data2/Users/aghyad/venv/lib/python3.10/site-packages/ray/_private/auto_init_hook.py", line 21, in auto_init_wrapper
    return fn(*args, **kwargs)
  File "/data2/Users/aghyad/venv/lib/python3.10/site-packages/ray/_private/client_mode_hook.py", line 103, in wrapper
    return func(*args, **kwargs)
  File "/data2/Users/aghyad/venv/lib/python3.10/site-packages/ray/_private/worker.py", line 2691, in get
    values, debugger_breakpoint = worker.get_objects(object_refs, timeout=timeout)
  File "/data2/Users/aghyad/venv/lib/python3.10/site-packages/ray/_private/worker.py", line 871, in get_objects
    raise value.as_instanceof_cause()
ray.exceptions.RayTaskError(FileNotFoundError): [36mray::unlearn()[39m (pid=910005, ip=64.255.46.66)
  File "/data2/Users/aghyad/publish_code_unlearn_eval/pipeline.py", line 183, in unlearn
    unlearn_corpus.main(
  File "/data2/Users/aghyad/publish_code_unlearn_eval/unlearn_corpus.py", line 538, in main
    retain_dataset = load_jsonl ([f"data/{file}.jsonl" for file in retain_files])
  File "/data2/Users/aghyad/publish_code_unlearn_eval/unlearn_corpus.py", line 422, in load_jsonl
    for line in open(file, "r"):
FileNotFoundError: [Errno 2] No such file or directory: 'data/fineweb_edu_seed-42/split_0.jsonl'
        

--- Error at 2024-10-06 19:26:39.054389-07:00 ---
            Exception in main:
[36mray::unlearn()[39m (pid=909291, ip=64.255.46.66)
  File "/data2/Users/aghyad/publish_code_unlearn_eval/pipeline.py", line 183, in unlearn
    unlearn_corpus.main(
  File "/data2/Users/aghyad/publish_code_unlearn_eval/unlearn_corpus.py", line 538, in main
    retain_dataset = load_jsonl ([f"data/{file}.jsonl" for file in retain_files])
  File "/data2/Users/aghyad/publish_code_unlearn_eval/unlearn_corpus.py", line 422, in load_jsonl
    for line in open(file, "r"):
FileNotFoundError: [Errno 2] No such file or directory: 'data/fineweb_edu_seed-42/split_0.jsonl'

            Traceback:
Traceback (most recent call last):
  File "/data2/Users/aghyad/publish_code_unlearn_eval/pipeline.py", line 392, in main
    ) = ray.get(ref)
  File "/data2/Users/aghyad/venv/lib/python3.10/site-packages/ray/_private/auto_init_hook.py", line 21, in auto_init_wrapper
    return fn(*args, **kwargs)
  File "/data2/Users/aghyad/venv/lib/python3.10/site-packages/ray/_private/client_mode_hook.py", line 103, in wrapper
    return func(*args, **kwargs)
  File "/data2/Users/aghyad/venv/lib/python3.10/site-packages/ray/_private/worker.py", line 2691, in get
    values, debugger_breakpoint = worker.get_objects(object_refs, timeout=timeout)
  File "/data2/Users/aghyad/venv/lib/python3.10/site-packages/ray/_private/worker.py", line 871, in get_objects
    raise value.as_instanceof_cause()
ray.exceptions.RayTaskError(FileNotFoundError): [36mray::unlearn()[39m (pid=909291, ip=64.255.46.66)
  File "/data2/Users/aghyad/publish_code_unlearn_eval/pipeline.py", line 183, in unlearn
    unlearn_corpus.main(
  File "/data2/Users/aghyad/publish_code_unlearn_eval/unlearn_corpus.py", line 538, in main
    retain_dataset = load_jsonl ([f"data/{file}.jsonl" for file in retain_files])
  File "/data2/Users/aghyad/publish_code_unlearn_eval/unlearn_corpus.py", line 422, in load_jsonl
    for line in open(file, "r"):
FileNotFoundError: [Errno 2] No such file or directory: 'data/fineweb_edu_seed-42/split_0.jsonl'
        

--- Error at 2024-10-06 19:27:21.709154-07:00 ---
            Exception in main:
[36mray::unlearn()[39m (pid=926139, ip=64.255.46.66)
  File "/data2/Users/aghyad/publish_code_unlearn_eval/pipeline.py", line 183, in unlearn
    unlearn_corpus.main(
  File "/data2/Users/aghyad/publish_code_unlearn_eval/unlearn_corpus.py", line 538, in main
    retain_dataset = load_jsonl ([f"data/{file}.jsonl" for file in retain_files])
  File "/data2/Users/aghyad/publish_code_unlearn_eval/unlearn_corpus.py", line 422, in load_jsonl
    for line in open(file, "r"):
FileNotFoundError: [Errno 2] No such file or directory: 'data/fineweb_edu_seed-42/split_0.jsonl'

            Traceback:
Traceback (most recent call last):
  File "/data2/Users/aghyad/publish_code_unlearn_eval/pipeline.py", line 392, in main
    ) = ray.get(ref)
  File "/data2/Users/aghyad/venv/lib/python3.10/site-packages/ray/_private/auto_init_hook.py", line 21, in auto_init_wrapper
    return fn(*args, **kwargs)
  File "/data2/Users/aghyad/venv/lib/python3.10/site-packages/ray/_private/client_mode_hook.py", line 103, in wrapper
    return func(*args, **kwargs)
  File "/data2/Users/aghyad/venv/lib/python3.10/site-packages/ray/_private/worker.py", line 2691, in get
    values, debugger_breakpoint = worker.get_objects(object_refs, timeout=timeout)
  File "/data2/Users/aghyad/venv/lib/python3.10/site-packages/ray/_private/worker.py", line 871, in get_objects
    raise value.as_instanceof_cause()
ray.exceptions.RayTaskError(FileNotFoundError): [36mray::unlearn()[39m (pid=926139, ip=64.255.46.66)
  File "/data2/Users/aghyad/publish_code_unlearn_eval/pipeline.py", line 183, in unlearn
    unlearn_corpus.main(
  File "/data2/Users/aghyad/publish_code_unlearn_eval/unlearn_corpus.py", line 538, in main
    retain_dataset = load_jsonl ([f"data/{file}.jsonl" for file in retain_files])
  File "/data2/Users/aghyad/publish_code_unlearn_eval/unlearn_corpus.py", line 422, in load_jsonl
    for line in open(file, "r"):
FileNotFoundError: [Errno 2] No such file or directory: 'data/fineweb_edu_seed-42/split_0.jsonl'
        

--- Error at 2024-10-06 19:27:21.735693-07:00 ---
            Exception in main:
[36mray::unlearn()[39m (pid=925897, ip=64.255.46.66)
  File "/data2/Users/aghyad/publish_code_unlearn_eval/pipeline.py", line 183, in unlearn
    unlearn_corpus.main(
  File "/data2/Users/aghyad/publish_code_unlearn_eval/unlearn_corpus.py", line 538, in main
    retain_dataset = load_jsonl ([f"data/{file}.jsonl" for file in retain_files])
  File "/data2/Users/aghyad/publish_code_unlearn_eval/unlearn_corpus.py", line 422, in load_jsonl
    for line in open(file, "r"):
FileNotFoundError: [Errno 2] No such file or directory: 'data/fineweb_edu_seed-42/split_0.jsonl'

            Traceback:
Traceback (most recent call last):
  File "/data2/Users/aghyad/publish_code_unlearn_eval/pipeline.py", line 392, in main
    ) = ray.get(ref)
  File "/data2/Users/aghyad/venv/lib/python3.10/site-packages/ray/_private/auto_init_hook.py", line 21, in auto_init_wrapper
    return fn(*args, **kwargs)
  File "/data2/Users/aghyad/venv/lib/python3.10/site-packages/ray/_private/client_mode_hook.py", line 103, in wrapper
    return func(*args, **kwargs)
  File "/data2/Users/aghyad/venv/lib/python3.10/site-packages/ray/_private/worker.py", line 2691, in get
    values, debugger_breakpoint = worker.get_objects(object_refs, timeout=timeout)
  File "/data2/Users/aghyad/venv/lib/python3.10/site-packages/ray/_private/worker.py", line 871, in get_objects
    raise value.as_instanceof_cause()
ray.exceptions.RayTaskError(FileNotFoundError): [36mray::unlearn()[39m (pid=925897, ip=64.255.46.66)
  File "/data2/Users/aghyad/publish_code_unlearn_eval/pipeline.py", line 183, in unlearn
    unlearn_corpus.main(
  File "/data2/Users/aghyad/publish_code_unlearn_eval/unlearn_corpus.py", line 538, in main
    retain_dataset = load_jsonl ([f"data/{file}.jsonl" for file in retain_files])
  File "/data2/Users/aghyad/publish_code_unlearn_eval/unlearn_corpus.py", line 422, in load_jsonl
    for line in open(file, "r"):
FileNotFoundError: [Errno 2] No such file or directory: 'data/fineweb_edu_seed-42/split_0.jsonl'
        

--- Error at 2024-10-06 19:27:22.122895-07:00 ---
            Exception in main:
[36mray::unlearn()[39m (pid=925939, ip=64.255.46.66)
  File "/data2/Users/aghyad/publish_code_unlearn_eval/pipeline.py", line 183, in unlearn
    unlearn_corpus.main(
  File "/data2/Users/aghyad/publish_code_unlearn_eval/unlearn_corpus.py", line 538, in main
    retain_dataset = load_jsonl ([f"data/{file}.jsonl" for file in retain_files])
  File "/data2/Users/aghyad/publish_code_unlearn_eval/unlearn_corpus.py", line 422, in load_jsonl
    for line in open(file, "r"):
FileNotFoundError: [Errno 2] No such file or directory: 'data/fineweb_edu_seed-42/split_0.jsonl'

            Traceback:
Traceback (most recent call last):
  File "/data2/Users/aghyad/publish_code_unlearn_eval/pipeline.py", line 392, in main
    ) = ray.get(ref)
  File "/data2/Users/aghyad/venv/lib/python3.10/site-packages/ray/_private/auto_init_hook.py", line 21, in auto_init_wrapper
    return fn(*args, **kwargs)
  File "/data2/Users/aghyad/venv/lib/python3.10/site-packages/ray/_private/client_mode_hook.py", line 103, in wrapper
    return func(*args, **kwargs)
  File "/data2/Users/aghyad/venv/lib/python3.10/site-packages/ray/_private/worker.py", line 2691, in get
    values, debugger_breakpoint = worker.get_objects(object_refs, timeout=timeout)
  File "/data2/Users/aghyad/venv/lib/python3.10/site-packages/ray/_private/worker.py", line 871, in get_objects
    raise value.as_instanceof_cause()
ray.exceptions.RayTaskError(FileNotFoundError): [36mray::unlearn()[39m (pid=925939, ip=64.255.46.66)
  File "/data2/Users/aghyad/publish_code_unlearn_eval/pipeline.py", line 183, in unlearn
    unlearn_corpus.main(
  File "/data2/Users/aghyad/publish_code_unlearn_eval/unlearn_corpus.py", line 538, in main
    retain_dataset = load_jsonl ([f"data/{file}.jsonl" for file in retain_files])
  File "/data2/Users/aghyad/publish_code_unlearn_eval/unlearn_corpus.py", line 422, in load_jsonl
    for line in open(file, "r"):
FileNotFoundError: [Errno 2] No such file or directory: 'data/fineweb_edu_seed-42/split_0.jsonl'
        

--- Error at 2024-10-06 19:27:22.262678-07:00 ---
            Exception in main:
[36mray::unlearn()[39m (pid=925658, ip=64.255.46.66)
  File "/data2/Users/aghyad/publish_code_unlearn_eval/pipeline.py", line 183, in unlearn
    unlearn_corpus.main(
  File "/data2/Users/aghyad/publish_code_unlearn_eval/unlearn_corpus.py", line 538, in main
    retain_dataset = load_jsonl ([f"data/{file}.jsonl" for file in retain_files])
  File "/data2/Users/aghyad/publish_code_unlearn_eval/unlearn_corpus.py", line 422, in load_jsonl
    for line in open(file, "r"):
FileNotFoundError: [Errno 2] No such file or directory: 'data/fineweb_edu_seed-42/split_0.jsonl'

            Traceback:
Traceback (most recent call last):
  File "/data2/Users/aghyad/publish_code_unlearn_eval/pipeline.py", line 392, in main
    ) = ray.get(ref)
  File "/data2/Users/aghyad/venv/lib/python3.10/site-packages/ray/_private/auto_init_hook.py", line 21, in auto_init_wrapper
    return fn(*args, **kwargs)
  File "/data2/Users/aghyad/venv/lib/python3.10/site-packages/ray/_private/client_mode_hook.py", line 103, in wrapper
    return func(*args, **kwargs)
  File "/data2/Users/aghyad/venv/lib/python3.10/site-packages/ray/_private/worker.py", line 2691, in get
    values, debugger_breakpoint = worker.get_objects(object_refs, timeout=timeout)
  File "/data2/Users/aghyad/venv/lib/python3.10/site-packages/ray/_private/worker.py", line 871, in get_objects
    raise value.as_instanceof_cause()
ray.exceptions.RayTaskError(FileNotFoundError): [36mray::unlearn()[39m (pid=925658, ip=64.255.46.66)
  File "/data2/Users/aghyad/publish_code_unlearn_eval/pipeline.py", line 183, in unlearn
    unlearn_corpus.main(
  File "/data2/Users/aghyad/publish_code_unlearn_eval/unlearn_corpus.py", line 538, in main
    retain_dataset = load_jsonl ([f"data/{file}.jsonl" for file in retain_files])
  File "/data2/Users/aghyad/publish_code_unlearn_eval/unlearn_corpus.py", line 422, in load_jsonl
    for line in open(file, "r"):
FileNotFoundError: [Errno 2] No such file or directory: 'data/fineweb_edu_seed-42/split_0.jsonl'
        

--- Error at 2024-10-06 19:27:22.486622-07:00 ---
            Exception in main:
[36mray::unlearn()[39m (pid=925864, ip=64.255.46.66)
  File "/data2/Users/aghyad/publish_code_unlearn_eval/pipeline.py", line 183, in unlearn
    unlearn_corpus.main(
  File "/data2/Users/aghyad/publish_code_unlearn_eval/unlearn_corpus.py", line 538, in main
    retain_dataset = load_jsonl ([f"data/{file}.jsonl" for file in retain_files])
  File "/data2/Users/aghyad/publish_code_unlearn_eval/unlearn_corpus.py", line 422, in load_jsonl
    for line in open(file, "r"):
FileNotFoundError: [Errno 2] No such file or directory: 'data/fineweb_edu_seed-42/split_0.jsonl'

            Traceback:
Traceback (most recent call last):
  File "/data2/Users/aghyad/publish_code_unlearn_eval/pipeline.py", line 392, in main
    ) = ray.get(ref)
  File "/data2/Users/aghyad/venv/lib/python3.10/site-packages/ray/_private/auto_init_hook.py", line 21, in auto_init_wrapper
    return fn(*args, **kwargs)
  File "/data2/Users/aghyad/venv/lib/python3.10/site-packages/ray/_private/client_mode_hook.py", line 103, in wrapper
    return func(*args, **kwargs)
  File "/data2/Users/aghyad/venv/lib/python3.10/site-packages/ray/_private/worker.py", line 2691, in get
    values, debugger_breakpoint = worker.get_objects(object_refs, timeout=timeout)
  File "/data2/Users/aghyad/venv/lib/python3.10/site-packages/ray/_private/worker.py", line 871, in get_objects
    raise value.as_instanceof_cause()
ray.exceptions.RayTaskError(FileNotFoundError): [36mray::unlearn()[39m (pid=925864, ip=64.255.46.66)
  File "/data2/Users/aghyad/publish_code_unlearn_eval/pipeline.py", line 183, in unlearn
    unlearn_corpus.main(
  File "/data2/Users/aghyad/publish_code_unlearn_eval/unlearn_corpus.py", line 538, in main
    retain_dataset = load_jsonl ([f"data/{file}.jsonl" for file in retain_files])
  File "/data2/Users/aghyad/publish_code_unlearn_eval/unlearn_corpus.py", line 422, in load_jsonl
    for line in open(file, "r"):
FileNotFoundError: [Errno 2] No such file or directory: 'data/fineweb_edu_seed-42/split_0.jsonl'
        

--- Error at 2024-10-06 19:27:22.661794-07:00 ---
            Exception in main:
[36mray::unlearn()[39m (pid=925998, ip=64.255.46.66)
  File "/data2/Users/aghyad/publish_code_unlearn_eval/pipeline.py", line 183, in unlearn
    unlearn_corpus.main(
  File "/data2/Users/aghyad/publish_code_unlearn_eval/unlearn_corpus.py", line 538, in main
    retain_dataset = load_jsonl ([f"data/{file}.jsonl" for file in retain_files])
  File "/data2/Users/aghyad/publish_code_unlearn_eval/unlearn_corpus.py", line 422, in load_jsonl
    for line in open(file, "r"):
FileNotFoundError: [Errno 2] No such file or directory: 'data/fineweb_edu_seed-42/split_0.jsonl'

            Traceback:
Traceback (most recent call last):
  File "/data2/Users/aghyad/publish_code_unlearn_eval/pipeline.py", line 392, in main
    ) = ray.get(ref)
  File "/data2/Users/aghyad/venv/lib/python3.10/site-packages/ray/_private/auto_init_hook.py", line 21, in auto_init_wrapper
    return fn(*args, **kwargs)
  File "/data2/Users/aghyad/venv/lib/python3.10/site-packages/ray/_private/client_mode_hook.py", line 103, in wrapper
    return func(*args, **kwargs)
  File "/data2/Users/aghyad/venv/lib/python3.10/site-packages/ray/_private/worker.py", line 2691, in get
    values, debugger_breakpoint = worker.get_objects(object_refs, timeout=timeout)
  File "/data2/Users/aghyad/venv/lib/python3.10/site-packages/ray/_private/worker.py", line 871, in get_objects
    raise value.as_instanceof_cause()
ray.exceptions.RayTaskError(FileNotFoundError): [36mray::unlearn()[39m (pid=925998, ip=64.255.46.66)
  File "/data2/Users/aghyad/publish_code_unlearn_eval/pipeline.py", line 183, in unlearn
    unlearn_corpus.main(
  File "/data2/Users/aghyad/publish_code_unlearn_eval/unlearn_corpus.py", line 538, in main
    retain_dataset = load_jsonl ([f"data/{file}.jsonl" for file in retain_files])
  File "/data2/Users/aghyad/publish_code_unlearn_eval/unlearn_corpus.py", line 422, in load_jsonl
    for line in open(file, "r"):
FileNotFoundError: [Errno 2] No such file or directory: 'data/fineweb_edu_seed-42/split_0.jsonl'
        

--- Error at 2024-10-06 19:27:23.167574-07:00 ---
            Exception in main:
[36mray::unlearn()[39m (pid=926196, ip=64.255.46.66)
  File "/data2/Users/aghyad/publish_code_unlearn_eval/pipeline.py", line 183, in unlearn
    unlearn_corpus.main(
  File "/data2/Users/aghyad/publish_code_unlearn_eval/unlearn_corpus.py", line 538, in main
    retain_dataset = load_jsonl ([f"data/{file}.jsonl" for file in retain_files])
  File "/data2/Users/aghyad/publish_code_unlearn_eval/unlearn_corpus.py", line 422, in load_jsonl
    for line in open(file, "r"):
FileNotFoundError: [Errno 2] No such file or directory: 'data/fineweb_edu_seed-42/split_0.jsonl'

            Traceback:
Traceback (most recent call last):
  File "/data2/Users/aghyad/publish_code_unlearn_eval/pipeline.py", line 392, in main
    ) = ray.get(ref)
  File "/data2/Users/aghyad/venv/lib/python3.10/site-packages/ray/_private/auto_init_hook.py", line 21, in auto_init_wrapper
    return fn(*args, **kwargs)
  File "/data2/Users/aghyad/venv/lib/python3.10/site-packages/ray/_private/client_mode_hook.py", line 103, in wrapper
    return func(*args, **kwargs)
  File "/data2/Users/aghyad/venv/lib/python3.10/site-packages/ray/_private/worker.py", line 2691, in get
    values, debugger_breakpoint = worker.get_objects(object_refs, timeout=timeout)
  File "/data2/Users/aghyad/venv/lib/python3.10/site-packages/ray/_private/worker.py", line 871, in get_objects
    raise value.as_instanceof_cause()
ray.exceptions.RayTaskError(FileNotFoundError): [36mray::unlearn()[39m (pid=926196, ip=64.255.46.66)
  File "/data2/Users/aghyad/publish_code_unlearn_eval/pipeline.py", line 183, in unlearn
    unlearn_corpus.main(
  File "/data2/Users/aghyad/publish_code_unlearn_eval/unlearn_corpus.py", line 538, in main
    retain_dataset = load_jsonl ([f"data/{file}.jsonl" for file in retain_files])
  File "/data2/Users/aghyad/publish_code_unlearn_eval/unlearn_corpus.py", line 422, in load_jsonl
    for line in open(file, "r"):
FileNotFoundError: [Errno 2] No such file or directory: 'data/fineweb_edu_seed-42/split_0.jsonl'
        

--- Error at 2024-10-06 19:27:32.093220-07:00 ---
            Exception in main:
[36mray::unlearn()[39m (pid=926007, ip=64.255.46.66)
  File "/data2/Users/aghyad/publish_code_unlearn_eval/pipeline.py", line 183, in unlearn
    unlearn_corpus.main(
  File "/data2/Users/aghyad/publish_code_unlearn_eval/unlearn_corpus.py", line 538, in main
    retain_dataset = load_jsonl ([f"data/{file}.jsonl" for file in retain_files])
  File "/data2/Users/aghyad/publish_code_unlearn_eval/unlearn_corpus.py", line 422, in load_jsonl
    for line in open(file, "r"):
FileNotFoundError: [Errno 2] No such file or directory: 'data/fineweb_edu_seed-42/split_0.jsonl'

            Traceback:
Traceback (most recent call last):
  File "/data2/Users/aghyad/publish_code_unlearn_eval/pipeline.py", line 392, in main
    ) = ray.get(ref)
  File "/data2/Users/aghyad/venv/lib/python3.10/site-packages/ray/_private/auto_init_hook.py", line 21, in auto_init_wrapper
    return fn(*args, **kwargs)
  File "/data2/Users/aghyad/venv/lib/python3.10/site-packages/ray/_private/client_mode_hook.py", line 103, in wrapper
    return func(*args, **kwargs)
  File "/data2/Users/aghyad/venv/lib/python3.10/site-packages/ray/_private/worker.py", line 2691, in get
    values, debugger_breakpoint = worker.get_objects(object_refs, timeout=timeout)
  File "/data2/Users/aghyad/venv/lib/python3.10/site-packages/ray/_private/worker.py", line 871, in get_objects
    raise value.as_instanceof_cause()
ray.exceptions.RayTaskError(FileNotFoundError): [36mray::unlearn()[39m (pid=926007, ip=64.255.46.66)
  File "/data2/Users/aghyad/publish_code_unlearn_eval/pipeline.py", line 183, in unlearn
    unlearn_corpus.main(
  File "/data2/Users/aghyad/publish_code_unlearn_eval/unlearn_corpus.py", line 538, in main
    retain_dataset = load_jsonl ([f"data/{file}.jsonl" for file in retain_files])
  File "/data2/Users/aghyad/publish_code_unlearn_eval/unlearn_corpus.py", line 422, in load_jsonl
    for line in open(file, "r"):
FileNotFoundError: [Errno 2] No such file or directory: 'data/fineweb_edu_seed-42/split_0.jsonl'
        

--- Error at 2024-10-06 19:27:32.485332-07:00 ---
            Exception in main:
[36mray::unlearn()[39m (pid=926106, ip=64.255.46.66)
  File "/data2/Users/aghyad/publish_code_unlearn_eval/pipeline.py", line 183, in unlearn
    unlearn_corpus.main(
  File "/data2/Users/aghyad/publish_code_unlearn_eval/unlearn_corpus.py", line 538, in main
    retain_dataset = load_jsonl ([f"data/{file}.jsonl" for file in retain_files])
  File "/data2/Users/aghyad/publish_code_unlearn_eval/unlearn_corpus.py", line 422, in load_jsonl
    for line in open(file, "r"):
FileNotFoundError: [Errno 2] No such file or directory: 'data/fineweb_edu_seed-42/split_0.jsonl'

            Traceback:
Traceback (most recent call last):
  File "/data2/Users/aghyad/publish_code_unlearn_eval/pipeline.py", line 392, in main
    ) = ray.get(ref)
  File "/data2/Users/aghyad/venv/lib/python3.10/site-packages/ray/_private/auto_init_hook.py", line 21, in auto_init_wrapper
    return fn(*args, **kwargs)
  File "/data2/Users/aghyad/venv/lib/python3.10/site-packages/ray/_private/client_mode_hook.py", line 103, in wrapper
    return func(*args, **kwargs)
  File "/data2/Users/aghyad/venv/lib/python3.10/site-packages/ray/_private/worker.py", line 2691, in get
    values, debugger_breakpoint = worker.get_objects(object_refs, timeout=timeout)
  File "/data2/Users/aghyad/venv/lib/python3.10/site-packages/ray/_private/worker.py", line 871, in get_objects
    raise value.as_instanceof_cause()
ray.exceptions.RayTaskError(FileNotFoundError): [36mray::unlearn()[39m (pid=926106, ip=64.255.46.66)
  File "/data2/Users/aghyad/publish_code_unlearn_eval/pipeline.py", line 183, in unlearn
    unlearn_corpus.main(
  File "/data2/Users/aghyad/publish_code_unlearn_eval/unlearn_corpus.py", line 538, in main
    retain_dataset = load_jsonl ([f"data/{file}.jsonl" for file in retain_files])
  File "/data2/Users/aghyad/publish_code_unlearn_eval/unlearn_corpus.py", line 422, in load_jsonl
    for line in open(file, "r"):
FileNotFoundError: [Errno 2] No such file or directory: 'data/fineweb_edu_seed-42/split_0.jsonl'
        

--- Error at 2024-10-06 19:27:32.973982-07:00 ---
            Exception in main:
[36mray::unlearn()[39m (pid=925828, ip=64.255.46.66)
  File "/data2/Users/aghyad/publish_code_unlearn_eval/pipeline.py", line 183, in unlearn
    unlearn_corpus.main(
  File "/data2/Users/aghyad/publish_code_unlearn_eval/unlearn_corpus.py", line 538, in main
    retain_dataset = load_jsonl ([f"data/{file}.jsonl" for file in retain_files])
  File "/data2/Users/aghyad/publish_code_unlearn_eval/unlearn_corpus.py", line 422, in load_jsonl
    for line in open(file, "r"):
FileNotFoundError: [Errno 2] No such file or directory: 'data/fineweb_edu_seed-42/split_0.jsonl'

            Traceback:
Traceback (most recent call last):
  File "/data2/Users/aghyad/publish_code_unlearn_eval/pipeline.py", line 392, in main
    ) = ray.get(ref)
  File "/data2/Users/aghyad/venv/lib/python3.10/site-packages/ray/_private/auto_init_hook.py", line 21, in auto_init_wrapper
    return fn(*args, **kwargs)
  File "/data2/Users/aghyad/venv/lib/python3.10/site-packages/ray/_private/client_mode_hook.py", line 103, in wrapper
    return func(*args, **kwargs)
  File "/data2/Users/aghyad/venv/lib/python3.10/site-packages/ray/_private/worker.py", line 2691, in get
    values, debugger_breakpoint = worker.get_objects(object_refs, timeout=timeout)
  File "/data2/Users/aghyad/venv/lib/python3.10/site-packages/ray/_private/worker.py", line 871, in get_objects
    raise value.as_instanceof_cause()
ray.exceptions.RayTaskError(FileNotFoundError): [36mray::unlearn()[39m (pid=925828, ip=64.255.46.66)
  File "/data2/Users/aghyad/publish_code_unlearn_eval/pipeline.py", line 183, in unlearn
    unlearn_corpus.main(
  File "/data2/Users/aghyad/publish_code_unlearn_eval/unlearn_corpus.py", line 538, in main
    retain_dataset = load_jsonl ([f"data/{file}.jsonl" for file in retain_files])
  File "/data2/Users/aghyad/publish_code_unlearn_eval/unlearn_corpus.py", line 422, in load_jsonl
    for line in open(file, "r"):
FileNotFoundError: [Errno 2] No such file or directory: 'data/fineweb_edu_seed-42/split_0.jsonl'
        

--- Error at 2024-10-06 19:27:34.147159-07:00 ---
            Exception in main:
[36mray::unlearn()[39m (pid=925781, ip=64.255.46.66)
  File "/data2/Users/aghyad/publish_code_unlearn_eval/pipeline.py", line 183, in unlearn
    unlearn_corpus.main(
  File "/data2/Users/aghyad/publish_code_unlearn_eval/unlearn_corpus.py", line 538, in main
    retain_dataset = load_jsonl ([f"data/{file}.jsonl" for file in retain_files])
  File "/data2/Users/aghyad/publish_code_unlearn_eval/unlearn_corpus.py", line 422, in load_jsonl
    for line in open(file, "r"):
FileNotFoundError: [Errno 2] No such file or directory: 'data/fineweb_edu_seed-42/split_0.jsonl'

            Traceback:
Traceback (most recent call last):
  File "/data2/Users/aghyad/publish_code_unlearn_eval/pipeline.py", line 392, in main
    ) = ray.get(ref)
  File "/data2/Users/aghyad/venv/lib/python3.10/site-packages/ray/_private/auto_init_hook.py", line 21, in auto_init_wrapper
    return fn(*args, **kwargs)
  File "/data2/Users/aghyad/venv/lib/python3.10/site-packages/ray/_private/client_mode_hook.py", line 103, in wrapper
    return func(*args, **kwargs)
  File "/data2/Users/aghyad/venv/lib/python3.10/site-packages/ray/_private/worker.py", line 2691, in get
    values, debugger_breakpoint = worker.get_objects(object_refs, timeout=timeout)
  File "/data2/Users/aghyad/venv/lib/python3.10/site-packages/ray/_private/worker.py", line 871, in get_objects
    raise value.as_instanceof_cause()
ray.exceptions.RayTaskError(FileNotFoundError): [36mray::unlearn()[39m (pid=925781, ip=64.255.46.66)
  File "/data2/Users/aghyad/publish_code_unlearn_eval/pipeline.py", line 183, in unlearn
    unlearn_corpus.main(
  File "/data2/Users/aghyad/publish_code_unlearn_eval/unlearn_corpus.py", line 538, in main
    retain_dataset = load_jsonl ([f"data/{file}.jsonl" for file in retain_files])
  File "/data2/Users/aghyad/publish_code_unlearn_eval/unlearn_corpus.py", line 422, in load_jsonl
    for line in open(file, "r"):
FileNotFoundError: [Errno 2] No such file or directory: 'data/fineweb_edu_seed-42/split_0.jsonl'
        

--- Error at 2024-10-06 19:27:34.275394-07:00 ---
            Exception in main:
[36mray::unlearn()[39m (pid=925851, ip=64.255.46.66)
  File "/data2/Users/aghyad/publish_code_unlearn_eval/pipeline.py", line 183, in unlearn
    unlearn_corpus.main(
  File "/data2/Users/aghyad/publish_code_unlearn_eval/unlearn_corpus.py", line 538, in main
    retain_dataset = load_jsonl ([f"data/{file}.jsonl" for file in retain_files])
  File "/data2/Users/aghyad/publish_code_unlearn_eval/unlearn_corpus.py", line 422, in load_jsonl
    for line in open(file, "r"):
FileNotFoundError: [Errno 2] No such file or directory: 'data/fineweb_edu_seed-42/split_0.jsonl'

            Traceback:
Traceback (most recent call last):
  File "/data2/Users/aghyad/publish_code_unlearn_eval/pipeline.py", line 392, in main
    ) = ray.get(ref)
  File "/data2/Users/aghyad/venv/lib/python3.10/site-packages/ray/_private/auto_init_hook.py", line 21, in auto_init_wrapper
    return fn(*args, **kwargs)
  File "/data2/Users/aghyad/venv/lib/python3.10/site-packages/ray/_private/client_mode_hook.py", line 103, in wrapper
    return func(*args, **kwargs)
  File "/data2/Users/aghyad/venv/lib/python3.10/site-packages/ray/_private/worker.py", line 2691, in get
    values, debugger_breakpoint = worker.get_objects(object_refs, timeout=timeout)
  File "/data2/Users/aghyad/venv/lib/python3.10/site-packages/ray/_private/worker.py", line 871, in get_objects
    raise value.as_instanceof_cause()
ray.exceptions.RayTaskError(FileNotFoundError): [36mray::unlearn()[39m (pid=925851, ip=64.255.46.66)
  File "/data2/Users/aghyad/publish_code_unlearn_eval/pipeline.py", line 183, in unlearn
    unlearn_corpus.main(
  File "/data2/Users/aghyad/publish_code_unlearn_eval/unlearn_corpus.py", line 538, in main
    retain_dataset = load_jsonl ([f"data/{file}.jsonl" for file in retain_files])
  File "/data2/Users/aghyad/publish_code_unlearn_eval/unlearn_corpus.py", line 422, in load_jsonl
    for line in open(file, "r"):
FileNotFoundError: [Errno 2] No such file or directory: 'data/fineweb_edu_seed-42/split_0.jsonl'
        

--- Error at 2024-10-06 19:27:34.458713-07:00 ---
            Exception in main:
[36mray::unlearn()[39m (pid=925866, ip=64.255.46.66)
  File "/data2/Users/aghyad/publish_code_unlearn_eval/pipeline.py", line 183, in unlearn
    unlearn_corpus.main(
  File "/data2/Users/aghyad/publish_code_unlearn_eval/unlearn_corpus.py", line 538, in main
    retain_dataset = load_jsonl ([f"data/{file}.jsonl" for file in retain_files])
  File "/data2/Users/aghyad/publish_code_unlearn_eval/unlearn_corpus.py", line 422, in load_jsonl
    for line in open(file, "r"):
FileNotFoundError: [Errno 2] No such file or directory: 'data/fineweb_edu_seed-42/split_0.jsonl'

            Traceback:
Traceback (most recent call last):
  File "/data2/Users/aghyad/publish_code_unlearn_eval/pipeline.py", line 392, in main
    ) = ray.get(ref)
  File "/data2/Users/aghyad/venv/lib/python3.10/site-packages/ray/_private/auto_init_hook.py", line 21, in auto_init_wrapper
    return fn(*args, **kwargs)
  File "/data2/Users/aghyad/venv/lib/python3.10/site-packages/ray/_private/client_mode_hook.py", line 103, in wrapper
    return func(*args, **kwargs)
  File "/data2/Users/aghyad/venv/lib/python3.10/site-packages/ray/_private/worker.py", line 2691, in get
    values, debugger_breakpoint = worker.get_objects(object_refs, timeout=timeout)
  File "/data2/Users/aghyad/venv/lib/python3.10/site-packages/ray/_private/worker.py", line 871, in get_objects
    raise value.as_instanceof_cause()
ray.exceptions.RayTaskError(FileNotFoundError): [36mray::unlearn()[39m (pid=925866, ip=64.255.46.66)
  File "/data2/Users/aghyad/publish_code_unlearn_eval/pipeline.py", line 183, in unlearn
    unlearn_corpus.main(
  File "/data2/Users/aghyad/publish_code_unlearn_eval/unlearn_corpus.py", line 538, in main
    retain_dataset = load_jsonl ([f"data/{file}.jsonl" for file in retain_files])
  File "/data2/Users/aghyad/publish_code_unlearn_eval/unlearn_corpus.py", line 422, in load_jsonl
    for line in open(file, "r"):
FileNotFoundError: [Errno 2] No such file or directory: 'data/fineweb_edu_seed-42/split_0.jsonl'
        

--- Error at 2024-10-06 19:27:34.749576-07:00 ---
            Exception in main:
[36mray::unlearn()[39m (pid=925775, ip=64.255.46.66)
  File "/data2/Users/aghyad/publish_code_unlearn_eval/pipeline.py", line 183, in unlearn
    unlearn_corpus.main(
  File "/data2/Users/aghyad/publish_code_unlearn_eval/unlearn_corpus.py", line 538, in main
    retain_dataset = load_jsonl ([f"data/{file}.jsonl" for file in retain_files])
  File "/data2/Users/aghyad/publish_code_unlearn_eval/unlearn_corpus.py", line 422, in load_jsonl
    for line in open(file, "r"):
FileNotFoundError: [Errno 2] No such file or directory: 'data/fineweb_edu_seed-42/split_0.jsonl'

            Traceback:
Traceback (most recent call last):
  File "/data2/Users/aghyad/publish_code_unlearn_eval/pipeline.py", line 392, in main
    ) = ray.get(ref)
  File "/data2/Users/aghyad/venv/lib/python3.10/site-packages/ray/_private/auto_init_hook.py", line 21, in auto_init_wrapper
    return fn(*args, **kwargs)
  File "/data2/Users/aghyad/venv/lib/python3.10/site-packages/ray/_private/client_mode_hook.py", line 103, in wrapper
    return func(*args, **kwargs)
  File "/data2/Users/aghyad/venv/lib/python3.10/site-packages/ray/_private/worker.py", line 2691, in get
    values, debugger_breakpoint = worker.get_objects(object_refs, timeout=timeout)
  File "/data2/Users/aghyad/venv/lib/python3.10/site-packages/ray/_private/worker.py", line 871, in get_objects
    raise value.as_instanceof_cause()
ray.exceptions.RayTaskError(FileNotFoundError): [36mray::unlearn()[39m (pid=925775, ip=64.255.46.66)
  File "/data2/Users/aghyad/publish_code_unlearn_eval/pipeline.py", line 183, in unlearn
    unlearn_corpus.main(
  File "/data2/Users/aghyad/publish_code_unlearn_eval/unlearn_corpus.py", line 538, in main
    retain_dataset = load_jsonl ([f"data/{file}.jsonl" for file in retain_files])
  File "/data2/Users/aghyad/publish_code_unlearn_eval/unlearn_corpus.py", line 422, in load_jsonl
    for line in open(file, "r"):
FileNotFoundError: [Errno 2] No such file or directory: 'data/fineweb_edu_seed-42/split_0.jsonl'
        

--- Error at 2024-10-06 19:27:42.237915-07:00 ---
            Exception in main:
[36mray::unlearn()[39m (pid=925343, ip=64.255.46.66)
  File "/data2/Users/aghyad/publish_code_unlearn_eval/pipeline.py", line 183, in unlearn
    unlearn_corpus.main(
  File "/data2/Users/aghyad/publish_code_unlearn_eval/unlearn_corpus.py", line 538, in main
    retain_dataset = load_jsonl ([f"data/{file}.jsonl" for file in retain_files])
  File "/data2/Users/aghyad/publish_code_unlearn_eval/unlearn_corpus.py", line 422, in load_jsonl
    for line in open(file, "r"):
FileNotFoundError: [Errno 2] No such file or directory: 'data/fineweb_edu_seed-42/split_0.jsonl'

            Traceback:
Traceback (most recent call last):
  File "/data2/Users/aghyad/publish_code_unlearn_eval/pipeline.py", line 392, in main
    ) = ray.get(ref)
  File "/data2/Users/aghyad/venv/lib/python3.10/site-packages/ray/_private/auto_init_hook.py", line 21, in auto_init_wrapper
    return fn(*args, **kwargs)
  File "/data2/Users/aghyad/venv/lib/python3.10/site-packages/ray/_private/client_mode_hook.py", line 103, in wrapper
    return func(*args, **kwargs)
  File "/data2/Users/aghyad/venv/lib/python3.10/site-packages/ray/_private/worker.py", line 2691, in get
    values, debugger_breakpoint = worker.get_objects(object_refs, timeout=timeout)
  File "/data2/Users/aghyad/venv/lib/python3.10/site-packages/ray/_private/worker.py", line 871, in get_objects
    raise value.as_instanceof_cause()
ray.exceptions.RayTaskError(FileNotFoundError): [36mray::unlearn()[39m (pid=925343, ip=64.255.46.66)
  File "/data2/Users/aghyad/publish_code_unlearn_eval/pipeline.py", line 183, in unlearn
    unlearn_corpus.main(
  File "/data2/Users/aghyad/publish_code_unlearn_eval/unlearn_corpus.py", line 538, in main
    retain_dataset = load_jsonl ([f"data/{file}.jsonl" for file in retain_files])
  File "/data2/Users/aghyad/publish_code_unlearn_eval/unlearn_corpus.py", line 422, in load_jsonl
    for line in open(file, "r"):
FileNotFoundError: [Errno 2] No such file or directory: 'data/fineweb_edu_seed-42/split_0.jsonl'
        

--- Error at 2024-10-06 19:27:43.162050-07:00 ---
            Exception in main:
[36mray::unlearn()[39m (pid=925712, ip=64.255.46.66)
  File "/data2/Users/aghyad/publish_code_unlearn_eval/pipeline.py", line 183, in unlearn
    unlearn_corpus.main(
  File "/data2/Users/aghyad/publish_code_unlearn_eval/unlearn_corpus.py", line 538, in main
    retain_dataset = load_jsonl ([f"data/{file}.jsonl" for file in retain_files])
  File "/data2/Users/aghyad/publish_code_unlearn_eval/unlearn_corpus.py", line 422, in load_jsonl
    for line in open(file, "r"):
FileNotFoundError: [Errno 2] No such file or directory: 'data/fineweb_edu_seed-42/split_0.jsonl'

            Traceback:
Traceback (most recent call last):
  File "/data2/Users/aghyad/publish_code_unlearn_eval/pipeline.py", line 392, in main
    ) = ray.get(ref)
  File "/data2/Users/aghyad/venv/lib/python3.10/site-packages/ray/_private/auto_init_hook.py", line 21, in auto_init_wrapper
    return fn(*args, **kwargs)
  File "/data2/Users/aghyad/venv/lib/python3.10/site-packages/ray/_private/client_mode_hook.py", line 103, in wrapper
    return func(*args, **kwargs)
  File "/data2/Users/aghyad/venv/lib/python3.10/site-packages/ray/_private/worker.py", line 2691, in get
    values, debugger_breakpoint = worker.get_objects(object_refs, timeout=timeout)
  File "/data2/Users/aghyad/venv/lib/python3.10/site-packages/ray/_private/worker.py", line 871, in get_objects
    raise value.as_instanceof_cause()
ray.exceptions.RayTaskError(FileNotFoundError): [36mray::unlearn()[39m (pid=925712, ip=64.255.46.66)
  File "/data2/Users/aghyad/publish_code_unlearn_eval/pipeline.py", line 183, in unlearn
    unlearn_corpus.main(
  File "/data2/Users/aghyad/publish_code_unlearn_eval/unlearn_corpus.py", line 538, in main
    retain_dataset = load_jsonl ([f"data/{file}.jsonl" for file in retain_files])
  File "/data2/Users/aghyad/publish_code_unlearn_eval/unlearn_corpus.py", line 422, in load_jsonl
    for line in open(file, "r"):
FileNotFoundError: [Errno 2] No such file or directory: 'data/fineweb_edu_seed-42/split_0.jsonl'
        

--- Error at 2024-10-06 19:27:43.722733-07:00 ---
            Exception in main:
[36mray::unlearn()[39m (pid=925446, ip=64.255.46.66)
  File "/data2/Users/aghyad/publish_code_unlearn_eval/pipeline.py", line 183, in unlearn
    unlearn_corpus.main(
  File "/data2/Users/aghyad/publish_code_unlearn_eval/unlearn_corpus.py", line 538, in main
    retain_dataset = load_jsonl ([f"data/{file}.jsonl" for file in retain_files])
  File "/data2/Users/aghyad/publish_code_unlearn_eval/unlearn_corpus.py", line 422, in load_jsonl
    for line in open(file, "r"):
FileNotFoundError: [Errno 2] No such file or directory: 'data/fineweb_edu_seed-42/split_0.jsonl'

            Traceback:
Traceback (most recent call last):
  File "/data2/Users/aghyad/publish_code_unlearn_eval/pipeline.py", line 392, in main
    ) = ray.get(ref)
  File "/data2/Users/aghyad/venv/lib/python3.10/site-packages/ray/_private/auto_init_hook.py", line 21, in auto_init_wrapper
    return fn(*args, **kwargs)
  File "/data2/Users/aghyad/venv/lib/python3.10/site-packages/ray/_private/client_mode_hook.py", line 103, in wrapper
    return func(*args, **kwargs)
  File "/data2/Users/aghyad/venv/lib/python3.10/site-packages/ray/_private/worker.py", line 2691, in get
    values, debugger_breakpoint = worker.get_objects(object_refs, timeout=timeout)
  File "/data2/Users/aghyad/venv/lib/python3.10/site-packages/ray/_private/worker.py", line 871, in get_objects
    raise value.as_instanceof_cause()
ray.exceptions.RayTaskError(FileNotFoundError): [36mray::unlearn()[39m (pid=925446, ip=64.255.46.66)
  File "/data2/Users/aghyad/publish_code_unlearn_eval/pipeline.py", line 183, in unlearn
    unlearn_corpus.main(
  File "/data2/Users/aghyad/publish_code_unlearn_eval/unlearn_corpus.py", line 538, in main
    retain_dataset = load_jsonl ([f"data/{file}.jsonl" for file in retain_files])
  File "/data2/Users/aghyad/publish_code_unlearn_eval/unlearn_corpus.py", line 422, in load_jsonl
    for line in open(file, "r"):
FileNotFoundError: [Errno 2] No such file or directory: 'data/fineweb_edu_seed-42/split_0.jsonl'
        

--- Error at 2024-10-06 19:27:44.583945-07:00 ---
            Exception in main:
[36mray::unlearn()[39m (pid=925492, ip=64.255.46.66)
  File "/data2/Users/aghyad/publish_code_unlearn_eval/pipeline.py", line 183, in unlearn
    unlearn_corpus.main(
  File "/data2/Users/aghyad/publish_code_unlearn_eval/unlearn_corpus.py", line 538, in main
    retain_dataset = load_jsonl ([f"data/{file}.jsonl" for file in retain_files])
  File "/data2/Users/aghyad/publish_code_unlearn_eval/unlearn_corpus.py", line 422, in load_jsonl
    for line in open(file, "r"):
FileNotFoundError: [Errno 2] No such file or directory: 'data/fineweb_edu_seed-42/split_0.jsonl'

            Traceback:
Traceback (most recent call last):
  File "/data2/Users/aghyad/publish_code_unlearn_eval/pipeline.py", line 392, in main
    ) = ray.get(ref)
  File "/data2/Users/aghyad/venv/lib/python3.10/site-packages/ray/_private/auto_init_hook.py", line 21, in auto_init_wrapper
    return fn(*args, **kwargs)
  File "/data2/Users/aghyad/venv/lib/python3.10/site-packages/ray/_private/client_mode_hook.py", line 103, in wrapper
    return func(*args, **kwargs)
  File "/data2/Users/aghyad/venv/lib/python3.10/site-packages/ray/_private/worker.py", line 2691, in get
    values, debugger_breakpoint = worker.get_objects(object_refs, timeout=timeout)
  File "/data2/Users/aghyad/venv/lib/python3.10/site-packages/ray/_private/worker.py", line 871, in get_objects
    raise value.as_instanceof_cause()
ray.exceptions.RayTaskError(FileNotFoundError): [36mray::unlearn()[39m (pid=925492, ip=64.255.46.66)
  File "/data2/Users/aghyad/publish_code_unlearn_eval/pipeline.py", line 183, in unlearn
    unlearn_corpus.main(
  File "/data2/Users/aghyad/publish_code_unlearn_eval/unlearn_corpus.py", line 538, in main
    retain_dataset = load_jsonl ([f"data/{file}.jsonl" for file in retain_files])
  File "/data2/Users/aghyad/publish_code_unlearn_eval/unlearn_corpus.py", line 422, in load_jsonl
    for line in open(file, "r"):
FileNotFoundError: [Errno 2] No such file or directory: 'data/fineweb_edu_seed-42/split_0.jsonl'
        